
2020-12-24 02:31:37,912 INFO: errors [in app.py:580]
2020-12-24 02:31:45,814 ERROR: Exception on /artists [GET] [in C:\Users\rabea\anaconda3\lib\site-packages\flask\app.py:1891]
Traceback (most recent call last):
  File "C:\Users\rabea\anaconda3\lib\site-packages\sqlalchemy\util\_collections.py", line 1020, in __call__
    return self.registry[key]
KeyError: <greenlet.greenlet object at 0x000002AC508D4680>

During handling of the above exception, another exception occurred:

Traceback (most recent call last):
  File "C:\Users\rabea\anaconda3\lib\site-packages\flask\app.py", line 2447, in wsgi_app
    response = self.full_dispatch_request()
  File "C:\Users\rabea\anaconda3\lib\site-packages\flask\app.py", line 1952, in full_dispatch_request
    rv = self.handle_user_exception(e)
  File "C:\Users\rabea\anaconda3\lib\site-packages\flask\app.py", line 1821, in handle_user_exception
    reraise(exc_type, exc_value, tb)
  File "C:\Users\rabea\anaconda3\lib\site-packages\flask\_compat.py", line 39, in reraise
    raise value
  File "C:\Users\rabea\anaconda3\lib\site-packages\flask\app.py", line 1950, in full_dispatch_request
    rv = self.dispatch_request()
  File "C:\Users\rabea\anaconda3\lib\site-packages\flask\app.py", line 1936, in dispatch_request
    return self.view_functions[rule.endpoint](**req.view_args)
  File "app.py", line 281, in artists
    artists = db.session.query(Artist).all()
  File "C:\Users\rabea\anaconda3\lib\site-packages\sqlalchemy\orm\scoping.py", line 163, in do
    return getattr(self.registry(), name)(*args, **kwargs)
  File "C:\Users\rabea\anaconda3\lib\site-packages\sqlalchemy\util\_collections.py", line 1022, in __call__
    return self.registry.setdefault(key, self.createfunc())
  File "C:\Users\rabea\anaconda3\lib\site-packages\sqlalchemy\orm\session.py", line 3286, in __call__
    return self.class_(**local_kw)
  File "C:\Users\rabea\anaconda3\lib\site-packages\flask_sqlalchemy\__init__.py", line 137, in __init__
    track_modifications = app.config['SQLALCHEMY_TRACK_MODIFICATIONS']
KeyError: 'SQLALCHEMY_TRACK_MODIFICATIONS'
2020-12-24 02:31:48,178 ERROR: Exception on /venues [GET] [in C:\Users\rabea\anaconda3\lib\site-packages\flask\app.py:1891]
Traceback (most recent call last):
  File "C:\Users\rabea\anaconda3\lib\site-packages\sqlalchemy\util\_collections.py", line 1020, in __call__
    return self.registry[key]
KeyError: <greenlet.greenlet object at 0x000002AC508D4E00>

During handling of the above exception, another exception occurred:

Traceback (most recent call last):
  File "C:\Users\rabea\anaconda3\lib\site-packages\flask\app.py", line 2447, in wsgi_app
    response = self.full_dispatch_request()
  File "C:\Users\rabea\anaconda3\lib\site-packages\flask\app.py", line 1952, in full_dispatch_request
    rv = self.handle_user_exception(e)
  File "C:\Users\rabea\anaconda3\lib\site-packages\flask\app.py", line 1821, in handle_user_exception
    reraise(exc_type, exc_value, tb)
  File "C:\Users\rabea\anaconda3\lib\site-packages\flask\_compat.py", line 39, in reraise
    raise value
  File "C:\Users\rabea\anaconda3\lib\site-packages\flask\app.py", line 1950, in full_dispatch_request
    rv = self.dispatch_request()
  File "C:\Users\rabea\anaconda3\lib\site-packages\flask\app.py", line 1936, in dispatch_request
    return self.view_functions[rule.endpoint](**req.view_args)
  File "app.py", line 139, in venues
    states = db.session.query(Venue.state,Venue.city).distinct().all()
  File "C:\Users\rabea\anaconda3\lib\site-packages\sqlalchemy\orm\scoping.py", line 163, in do
    return getattr(self.registry(), name)(*args, **kwargs)
  File "C:\Users\rabea\anaconda3\lib\site-packages\sqlalchemy\util\_collections.py", line 1022, in __call__
    return self.registry.setdefault(key, self.createfunc())
  File "C:\Users\rabea\anaconda3\lib\site-packages\sqlalchemy\orm\session.py", line 3286, in __call__
    return self.class_(**local_kw)
  File "C:\Users\rabea\anaconda3\lib\site-packages\flask_sqlalchemy\__init__.py", line 137, in __init__
    track_modifications = app.config['SQLALCHEMY_TRACK_MODIFICATIONS']
KeyError: 'SQLALCHEMY_TRACK_MODIFICATIONS'
2020-12-24 02:31:52,839 ERROR: Exception on /artists [GET] [in C:\Users\rabea\anaconda3\lib\site-packages\flask\app.py:1891]
Traceback (most recent call last):
  File "C:\Users\rabea\anaconda3\lib\site-packages\sqlalchemy\util\_collections.py", line 1020, in __call__
    return self.registry[key]
KeyError: <greenlet.greenlet object at 0x000002AC508D4EA0>

During handling of the above exception, another exception occurred:

Traceback (most recent call last):
  File "C:\Users\rabea\anaconda3\lib\site-packages\flask\app.py", line 2447, in wsgi_app
    response = self.full_dispatch_request()
  File "C:\Users\rabea\anaconda3\lib\site-packages\flask\app.py", line 1952, in full_dispatch_request
    rv = self.handle_user_exception(e)
  File "C:\Users\rabea\anaconda3\lib\site-packages\flask\app.py", line 1821, in handle_user_exception
    reraise(exc_type, exc_value, tb)
  File "C:\Users\rabea\anaconda3\lib\site-packages\flask\_compat.py", line 39, in reraise
    raise value
  File "C:\Users\rabea\anaconda3\lib\site-packages\flask\app.py", line 1950, in full_dispatch_request
    rv = self.dispatch_request()
  File "C:\Users\rabea\anaconda3\lib\site-packages\flask\app.py", line 1936, in dispatch_request
    return self.view_functions[rule.endpoint](**req.view_args)
  File "app.py", line 281, in artists
    artists = db.session.query(Artist).all()
  File "C:\Users\rabea\anaconda3\lib\site-packages\sqlalchemy\orm\scoping.py", line 163, in do
    return getattr(self.registry(), name)(*args, **kwargs)
  File "C:\Users\rabea\anaconda3\lib\site-packages\sqlalchemy\util\_collections.py", line 1022, in __call__
    return self.registry.setdefault(key, self.createfunc())
  File "C:\Users\rabea\anaconda3\lib\site-packages\sqlalchemy\orm\session.py", line 3286, in __call__
    return self.class_(**local_kw)
  File "C:\Users\rabea\anaconda3\lib\site-packages\flask_sqlalchemy\__init__.py", line 137, in __init__
    track_modifications = app.config['SQLALCHEMY_TRACK_MODIFICATIONS']
KeyError: 'SQLALCHEMY_TRACK_MODIFICATIONS'
2020-12-24 02:32:44,834 ERROR: Exception on /artists [GET] [in C:\Users\rabea\anaconda3\lib\site-packages\flask\app.py:1891]
Traceback (most recent call last):
  File "C:\Users\rabea\anaconda3\lib\site-packages\sqlalchemy\util\_collections.py", line 1020, in __call__
    return self.registry[key]
KeyError: <greenlet.greenlet object at 0x000002AC508D4E00>

During handling of the above exception, another exception occurred:

Traceback (most recent call last):
  File "C:\Users\rabea\anaconda3\lib\site-packages\flask\app.py", line 2447, in wsgi_app
    response = self.full_dispatch_request()
  File "C:\Users\rabea\anaconda3\lib\site-packages\flask\app.py", line 1952, in full_dispatch_request
    rv = self.handle_user_exception(e)
  File "C:\Users\rabea\anaconda3\lib\site-packages\flask\app.py", line 1821, in handle_user_exception
    reraise(exc_type, exc_value, tb)
  File "C:\Users\rabea\anaconda3\lib\site-packages\flask\_compat.py", line 39, in reraise
    raise value
  File "C:\Users\rabea\anaconda3\lib\site-packages\flask\app.py", line 1950, in full_dispatch_request
    rv = self.dispatch_request()
  File "C:\Users\rabea\anaconda3\lib\site-packages\flask\app.py", line 1936, in dispatch_request
    return self.view_functions[rule.endpoint](**req.view_args)
  File "app.py", line 281, in artists
    # TODO: replace with real data returned from querying the database
  File "C:\Users\rabea\anaconda3\lib\site-packages\sqlalchemy\orm\scoping.py", line 163, in do
    return getattr(self.registry(), name)(*args, **kwargs)
  File "C:\Users\rabea\anaconda3\lib\site-packages\sqlalchemy\util\_collections.py", line 1022, in __call__
    return self.registry.setdefault(key, self.createfunc())
  File "C:\Users\rabea\anaconda3\lib\site-packages\sqlalchemy\orm\session.py", line 3286, in __call__
    return self.class_(**local_kw)
  File "C:\Users\rabea\anaconda3\lib\site-packages\flask_sqlalchemy\__init__.py", line 137, in __init__
    track_modifications = app.config['SQLALCHEMY_TRACK_MODIFICATIONS']
KeyError: 'SQLALCHEMY_TRACK_MODIFICATIONS'
2020-12-24 02:32:48,380 ERROR: Exception on /venues [GET] [in C:\Users\rabea\anaconda3\lib\site-packages\flask\app.py:1891]
Traceback (most recent call last):
  File "C:\Users\rabea\anaconda3\lib\site-packages\sqlalchemy\util\_collections.py", line 1020, in __call__
    return self.registry[key]
KeyError: <greenlet.greenlet object at 0x000002AC508D4680>

During handling of the above exception, another exception occurred:

Traceback (most recent call last):
  File "C:\Users\rabea\anaconda3\lib\site-packages\flask\app.py", line 2447, in wsgi_app
    response = self.full_dispatch_request()
  File "C:\Users\rabea\anaconda3\lib\site-packages\flask\app.py", line 1952, in full_dispatch_request
    rv = self.handle_user_exception(e)
  File "C:\Users\rabea\anaconda3\lib\site-packages\flask\app.py", line 1821, in handle_user_exception
    reraise(exc_type, exc_value, tb)
  File "C:\Users\rabea\anaconda3\lib\site-packages\flask\_compat.py", line 39, in reraise
    raise value
  File "C:\Users\rabea\anaconda3\lib\site-packages\flask\app.py", line 1950, in full_dispatch_request
    rv = self.dispatch_request()
  File "C:\Users\rabea\anaconda3\lib\site-packages\flask\app.py", line 1936, in dispatch_request
    return self.view_functions[rule.endpoint](**req.view_args)
  File "app.py", line 139, in venues
    #       num_shows should be aggregated based on number of upcoming shows per venue.
  File "C:\Users\rabea\anaconda3\lib\site-packages\sqlalchemy\orm\scoping.py", line 163, in do
    return getattr(self.registry(), name)(*args, **kwargs)
  File "C:\Users\rabea\anaconda3\lib\site-packages\sqlalchemy\util\_collections.py", line 1022, in __call__
    return self.registry.setdefault(key, self.createfunc())
  File "C:\Users\rabea\anaconda3\lib\site-packages\sqlalchemy\orm\session.py", line 3286, in __call__
    return self.class_(**local_kw)
  File "C:\Users\rabea\anaconda3\lib\site-packages\flask_sqlalchemy\__init__.py", line 137, in __init__
    track_modifications = app.config['SQLALCHEMY_TRACK_MODIFICATIONS']
KeyError: 'SQLALCHEMY_TRACK_MODIFICATIONS'
2020-12-24 02:32:49,322 ERROR: Exception on /artists [GET] [in C:\Users\rabea\anaconda3\lib\site-packages\flask\app.py:1891]
Traceback (most recent call last):
  File "C:\Users\rabea\anaconda3\lib\site-packages\sqlalchemy\util\_collections.py", line 1020, in __call__
    return self.registry[key]
KeyError: <greenlet.greenlet object at 0x000002AC508D4F40>

During handling of the above exception, another exception occurred:

Traceback (most recent call last):
  File "C:\Users\rabea\anaconda3\lib\site-packages\flask\app.py", line 2447, in wsgi_app
    response = self.full_dispatch_request()
  File "C:\Users\rabea\anaconda3\lib\site-packages\flask\app.py", line 1952, in full_dispatch_request
    rv = self.handle_user_exception(e)
  File "C:\Users\rabea\anaconda3\lib\site-packages\flask\app.py", line 1821, in handle_user_exception
    reraise(exc_type, exc_value, tb)
  File "C:\Users\rabea\anaconda3\lib\site-packages\flask\_compat.py", line 39, in reraise
    raise value
  File "C:\Users\rabea\anaconda3\lib\site-packages\flask\app.py", line 1950, in full_dispatch_request
    rv = self.dispatch_request()
  File "C:\Users\rabea\anaconda3\lib\site-packages\flask\app.py", line 1936, in dispatch_request
    return self.view_functions[rule.endpoint](**req.view_args)
  File "app.py", line 281, in artists
    # TODO: replace with real data returned from querying the database
  File "C:\Users\rabea\anaconda3\lib\site-packages\sqlalchemy\orm\scoping.py", line 163, in do
    return getattr(self.registry(), name)(*args, **kwargs)
  File "C:\Users\rabea\anaconda3\lib\site-packages\sqlalchemy\util\_collections.py", line 1022, in __call__
    return self.registry.setdefault(key, self.createfunc())
  File "C:\Users\rabea\anaconda3\lib\site-packages\sqlalchemy\orm\session.py", line 3286, in __call__
    return self.class_(**local_kw)
  File "C:\Users\rabea\anaconda3\lib\site-packages\flask_sqlalchemy\__init__.py", line 137, in __init__
    track_modifications = app.config['SQLALCHEMY_TRACK_MODIFICATIONS']
KeyError: 'SQLALCHEMY_TRACK_MODIFICATIONS'
2020-12-24 02:32:50,272 ERROR: Exception on /shows [GET] [in C:\Users\rabea\anaconda3\lib\site-packages\flask\app.py:1891]
Traceback (most recent call last):
  File "C:\Users\rabea\anaconda3\lib\site-packages\sqlalchemy\util\_collections.py", line 1020, in __call__
    return self.registry[key]
KeyError: <greenlet.greenlet object at 0x000002AC50AC0040>

During handling of the above exception, another exception occurred:

Traceback (most recent call last):
  File "C:\Users\rabea\anaconda3\lib\site-packages\flask\app.py", line 2447, in wsgi_app
    response = self.full_dispatch_request()
  File "C:\Users\rabea\anaconda3\lib\site-packages\flask\app.py", line 1952, in full_dispatch_request
    rv = self.handle_user_exception(e)
  File "C:\Users\rabea\anaconda3\lib\site-packages\flask\app.py", line 1821, in handle_user_exception
    reraise(exc_type, exc_value, tb)
  File "C:\Users\rabea\anaconda3\lib\site-packages\flask\_compat.py", line 39, in reraise
    raise value
  File "C:\Users\rabea\anaconda3\lib\site-packages\flask\app.py", line 1950, in full_dispatch_request
    rv = self.dispatch_request()
  File "C:\Users\rabea\anaconda3\lib\site-packages\flask\app.py", line 1936, in dispatch_request
    return self.view_functions[rule.endpoint](**req.view_args)
  File "app.py", line 511, in shows
    # shows=db.session.query(Show, Show,a).join(Show).all()
  File "C:\Users\rabea\anaconda3\lib\site-packages\sqlalchemy\orm\scoping.py", line 163, in do
    return getattr(self.registry(), name)(*args, **kwargs)
  File "C:\Users\rabea\anaconda3\lib\site-packages\sqlalchemy\util\_collections.py", line 1022, in __call__
    return self.registry.setdefault(key, self.createfunc())
  File "C:\Users\rabea\anaconda3\lib\site-packages\sqlalchemy\orm\session.py", line 3286, in __call__
    return self.class_(**local_kw)
  File "C:\Users\rabea\anaconda3\lib\site-packages\flask_sqlalchemy\__init__.py", line 137, in __init__
    track_modifications = app.config['SQLALCHEMY_TRACK_MODIFICATIONS']
KeyError: 'SQLALCHEMY_TRACK_MODIFICATIONS'
2020-12-24 02:32:53,614 ERROR: Exception on /artists [GET] [in C:\Users\rabea\anaconda3\lib\site-packages\flask\app.py:1891]
Traceback (most recent call last):
  File "C:\Users\rabea\anaconda3\lib\site-packages\sqlalchemy\util\_collections.py", line 1020, in __call__
    return self.registry[key]
KeyError: <greenlet.greenlet object at 0x000002AC50AC0180>

During handling of the above exception, another exception occurred:

Traceback (most recent call last):
  File "C:\Users\rabea\anaconda3\lib\site-packages\flask\app.py", line 2447, in wsgi_app
    response = self.full_dispatch_request()
  File "C:\Users\rabea\anaconda3\lib\site-packages\flask\app.py", line 1952, in full_dispatch_request
    rv = self.handle_user_exception(e)
  File "C:\Users\rabea\anaconda3\lib\site-packages\flask\app.py", line 1821, in handle_user_exception
    reraise(exc_type, exc_value, tb)
  File "C:\Users\rabea\anaconda3\lib\site-packages\flask\_compat.py", line 39, in reraise
    raise value
  File "C:\Users\rabea\anaconda3\lib\site-packages\flask\app.py", line 1950, in full_dispatch_request
    rv = self.dispatch_request()
  File "C:\Users\rabea\anaconda3\lib\site-packages\flask\app.py", line 1936, in dispatch_request
    return self.view_functions[rule.endpoint](**req.view_args)
  File "app.py", line 281, in artists
    # TODO: replace with real data returned from querying the database
  File "C:\Users\rabea\anaconda3\lib\site-packages\sqlalchemy\orm\scoping.py", line 163, in do
    return getattr(self.registry(), name)(*args, **kwargs)
  File "C:\Users\rabea\anaconda3\lib\site-packages\sqlalchemy\util\_collections.py", line 1022, in __call__
    return self.registry.setdefault(key, self.createfunc())
  File "C:\Users\rabea\anaconda3\lib\site-packages\sqlalchemy\orm\session.py", line 3286, in __call__
    return self.class_(**local_kw)
  File "C:\Users\rabea\anaconda3\lib\site-packages\flask_sqlalchemy\__init__.py", line 137, in __init__
    track_modifications = app.config['SQLALCHEMY_TRACK_MODIFICATIONS']
KeyError: 'SQLALCHEMY_TRACK_MODIFICATIONS'
2020-12-24 02:33:24,817 ERROR: Exception on /artists [GET] [in C:\Users\rabea\anaconda3\lib\site-packages\flask\app.py:1891]
Traceback (most recent call last):
  File "C:\Users\rabea\anaconda3\lib\site-packages\sqlalchemy\util\_collections.py", line 1020, in __call__
    return self.registry[key]
KeyError: <greenlet.greenlet object at 0x000002AC50AC0220>

During handling of the above exception, another exception occurred:

Traceback (most recent call last):
  File "C:\Users\rabea\anaconda3\lib\site-packages\flask\app.py", line 2447, in wsgi_app
    response = self.full_dispatch_request()
  File "C:\Users\rabea\anaconda3\lib\site-packages\flask\app.py", line 1952, in full_dispatch_request
    rv = self.handle_user_exception(e)
  File "C:\Users\rabea\anaconda3\lib\site-packages\flask\app.py", line 1821, in handle_user_exception
    reraise(exc_type, exc_value, tb)
  File "C:\Users\rabea\anaconda3\lib\site-packages\flask\_compat.py", line 39, in reraise
    raise value
  File "C:\Users\rabea\anaconda3\lib\site-packages\flask\app.py", line 1950, in full_dispatch_request
    rv = self.dispatch_request()
  File "C:\Users\rabea\anaconda3\lib\site-packages\flask\app.py", line 1936, in dispatch_request
    return self.view_functions[rule.endpoint](**req.view_args)
  File "app.py", line 281, in artists
    # TODO: replace with real data returned from querying the database
  File "C:\Users\rabea\anaconda3\lib\site-packages\sqlalchemy\orm\scoping.py", line 163, in do
    return getattr(self.registry(), name)(*args, **kwargs)
  File "C:\Users\rabea\anaconda3\lib\site-packages\sqlalchemy\util\_collections.py", line 1022, in __call__
    return self.registry.setdefault(key, self.createfunc())
  File "C:\Users\rabea\anaconda3\lib\site-packages\sqlalchemy\orm\session.py", line 3286, in __call__
    return self.class_(**local_kw)
  File "C:\Users\rabea\anaconda3\lib\site-packages\flask_sqlalchemy\__init__.py", line 137, in __init__
    track_modifications = app.config['SQLALCHEMY_TRACK_MODIFICATIONS']
KeyError: 'SQLALCHEMY_TRACK_MODIFICATIONS'
2022-05-30 10:20:37,692 INFO: errors [in C:\Users\a.ahmed\Desktop\fyyur-main\app.py:552]
2022-05-30 10:46:55,609 INFO: errors [in C:\Users\a.ahmed\Desktop\fyyur-main\app.py:552]
2022-05-30 11:34:46,718 INFO: errors [in C:\Users\a.ahmed\Desktop\artist-booking-fyyur\app.py:552]
